EssssssssssssssssssssssssssssssssssssssssssssssssssssssssssEEsssssssssssssssssssssssssssssssssssssssssssssssssssssssssssssssssssssssssssssssssssssssssssssssssssssssssss
======================================================================
ERROR: test_console (unittest.loader.ModuleImportFailure)
----------------------------------------------------------------------
Traceback (most recent call last):
  File "/usr/lib/python3.4/unittest/case.py", line 58, in testPartExecutor
    yield
  File "/usr/lib/python3.4/unittest/case.py", line 577, in run
    testMethod()
  File "/usr/lib/python3.4/unittest/loader.py", line 32, in testFailure
    raise exception
ImportError: Failed to import test module: test_console
Traceback (most recent call last):
  File "/usr/local/lib/python3.4/dist-packages/sqlalchemy/engine/base.py", line 2158, in _wrap_pool_connect
    return fn()
  File "/usr/local/lib/python3.4/dist-packages/sqlalchemy/pool.py", line 403, in connect
    return _ConnectionFairy._checkout(self)
  File "/usr/local/lib/python3.4/dist-packages/sqlalchemy/pool.py", line 784, in _checkout
    fairy = _ConnectionRecord.checkout(pool)
  File "/usr/local/lib/python3.4/dist-packages/sqlalchemy/pool.py", line 532, in checkout
    rec = pool._do_get()
  File "/usr/local/lib/python3.4/dist-packages/sqlalchemy/pool.py", line 1189, in _do_get
    self._dec_overflow()
  File "/usr/local/lib/python3.4/dist-packages/sqlalchemy/util/langhelpers.py", line 66, in __exit__
    compat.reraise(exc_type, exc_value, exc_tb)
  File "/usr/local/lib/python3.4/dist-packages/sqlalchemy/util/compat.py", line 187, in reraise
    raise value
  File "/usr/local/lib/python3.4/dist-packages/sqlalchemy/pool.py", line 1186, in _do_get
    return self._create_connection()
  File "/usr/local/lib/python3.4/dist-packages/sqlalchemy/pool.py", line 350, in _create_connection
    return _ConnectionRecord(self)
  File "/usr/local/lib/python3.4/dist-packages/sqlalchemy/pool.py", line 477, in __init__
    self.__connect(first_connect_check=True)
  File "/usr/local/lib/python3.4/dist-packages/sqlalchemy/pool.py", line 667, in __connect
    connection = pool._invoke_creator(self)
  File "/usr/local/lib/python3.4/dist-packages/sqlalchemy/engine/strategies.py", line 106, in connect
    return dialect.connect(*cargs, **cparams)
  File "/usr/local/lib/python3.4/dist-packages/sqlalchemy/engine/default.py", line 410, in connect
    return self.dbapi.connect(*cargs, **cparams)
  File "/usr/local/lib/python3.4/dist-packages/MySQLdb/__init__.py", line 86, in Connect
    return Connection(*args, **kwargs)
  File "/usr/local/lib/python3.4/dist-packages/MySQLdb/connections.py", line 204, in __init__
    super(Connection, self).__init__(*args, **kwargs2)
_mysql_exceptions.OperationalError: (1045, "Access denied for user 'hbnb_test'@'localhost' (using password: YES)")

The above exception was the direct cause of the following exception:

Traceback (most recent call last):
  File "/usr/lib/python3.4/unittest/loader.py", line 312, in _find_tests
    module = self._get_module_from_name(name)
  File "/usr/lib/python3.4/unittest/loader.py", line 290, in _get_module_from_name
    __import__(name)
  File "/home/vagrant/Holberton/AirBnB_clone_v2/tests/test_console.py", line 3, in <module>
    from models.engine.file_storage import FileStorage
  File "/home/vagrant/Holberton/AirBnB_clone_v2/models/__init__.py", line 16, in <module>
    storage = DBStorage()
  File "/home/vagrant/Holberton/AirBnB_clone_v2/models/engine/db_storage.py", line 37, in __init__
    Base.metadata.drop_all(bind=self.__engine)
  File "/usr/local/lib/python3.4/dist-packages/sqlalchemy/sql/schema.py", line 4031, in drop_all
    tables=tables)
  File "/usr/local/lib/python3.4/dist-packages/sqlalchemy/engine/base.py", line 1939, in _run_visitor
    with self._optional_conn_ctx_manager(connection) as conn:
  File "/usr/lib/python3.4/contextlib.py", line 59, in __enter__
    return next(self.gen)
  File "/usr/local/lib/python3.4/dist-packages/sqlalchemy/engine/base.py", line 1932, in _optional_conn_ctx_manager
    with self.contextual_connect() as conn:
  File "/usr/local/lib/python3.4/dist-packages/sqlalchemy/engine/base.py", line 2123, in contextual_connect
    self._wrap_pool_connect(self.pool.connect, None),
  File "/usr/local/lib/python3.4/dist-packages/sqlalchemy/engine/base.py", line 2162, in _wrap_pool_connect
    e, dialect, self)
  File "/usr/local/lib/python3.4/dist-packages/sqlalchemy/engine/base.py", line 1476, in _handle_dbapi_exception_noconnection
    exc_info
  File "/usr/local/lib/python3.4/dist-packages/sqlalchemy/util/compat.py", line 203, in raise_from_cause
    reraise(type(exception), exception, tb=exc_tb, cause=cause)
  File "/usr/local/lib/python3.4/dist-packages/sqlalchemy/util/compat.py", line 186, in reraise
    raise value.with_traceback(tb)
  File "/usr/local/lib/python3.4/dist-packages/sqlalchemy/engine/base.py", line 2158, in _wrap_pool_connect
    return fn()
  File "/usr/local/lib/python3.4/dist-packages/sqlalchemy/pool.py", line 403, in connect
    return _ConnectionFairy._checkout(self)
  File "/usr/local/lib/python3.4/dist-packages/sqlalchemy/pool.py", line 784, in _checkout
    fairy = _ConnectionRecord.checkout(pool)
  File "/usr/local/lib/python3.4/dist-packages/sqlalchemy/pool.py", line 532, in checkout
    rec = pool._do_get()
  File "/usr/local/lib/python3.4/dist-packages/sqlalchemy/pool.py", line 1189, in _do_get
    self._dec_overflow()
  File "/usr/local/lib/python3.4/dist-packages/sqlalchemy/util/langhelpers.py", line 66, in __exit__
    compat.reraise(exc_type, exc_value, exc_tb)
  File "/usr/local/lib/python3.4/dist-packages/sqlalchemy/util/compat.py", line 187, in reraise
    raise value
  File "/usr/local/lib/python3.4/dist-packages/sqlalchemy/pool.py", line 1186, in _do_get
    return self._create_connection()
  File "/usr/local/lib/python3.4/dist-packages/sqlalchemy/pool.py", line 350, in _create_connection
    return _ConnectionRecord(self)
  File "/usr/local/lib/python3.4/dist-packages/sqlalchemy/pool.py", line 477, in __init__
    self.__connect(first_connect_check=True)
  File "/usr/local/lib/python3.4/dist-packages/sqlalchemy/pool.py", line 667, in __connect
    connection = pool._invoke_creator(self)
  File "/usr/local/lib/python3.4/dist-packages/sqlalchemy/engine/strategies.py", line 106, in connect
    return dialect.connect(*cargs, **cparams)
  File "/usr/local/lib/python3.4/dist-packages/sqlalchemy/engine/default.py", line 410, in connect
    return self.dbapi.connect(*cargs, **cparams)
  File "/usr/local/lib/python3.4/dist-packages/MySQLdb/__init__.py", line 86, in Connect
    return Connection(*args, **kwargs)
  File "/usr/local/lib/python3.4/dist-packages/MySQLdb/connections.py", line 204, in __init__
    super(Connection, self).__init__(*args, **kwargs2)
sqlalchemy.exc.OperationalError: (_mysql_exceptions.OperationalError) (1045, "Access denied for user 'hbnb_test'@'localhost' (using password: YES)") (Background on this error at: http://sqlalche.me/e/e3q8)


======================================================================
ERROR: test_models.test_engine.test_db_storage (unittest.loader.ModuleImportFailure)
----------------------------------------------------------------------
Traceback (most recent call last):
  File "/usr/lib/python3.4/unittest/case.py", line 58, in testPartExecutor
    yield
  File "/usr/lib/python3.4/unittest/case.py", line 577, in run
    testMethod()
  File "/usr/lib/python3.4/unittest/loader.py", line 32, in testFailure
    raise exception
ImportError: Failed to import test module: test_models.test_engine.test_db_storage
Traceback (most recent call last):
  File "/usr/local/lib/python3.4/dist-packages/sqlalchemy/engine/base.py", line 2158, in _wrap_pool_connect
    return fn()
  File "/usr/local/lib/python3.4/dist-packages/sqlalchemy/pool.py", line 403, in connect
    return _ConnectionFairy._checkout(self)
  File "/usr/local/lib/python3.4/dist-packages/sqlalchemy/pool.py", line 784, in _checkout
    fairy = _ConnectionRecord.checkout(pool)
  File "/usr/local/lib/python3.4/dist-packages/sqlalchemy/pool.py", line 532, in checkout
    rec = pool._do_get()
  File "/usr/local/lib/python3.4/dist-packages/sqlalchemy/pool.py", line 1189, in _do_get
    self._dec_overflow()
  File "/usr/local/lib/python3.4/dist-packages/sqlalchemy/util/langhelpers.py", line 66, in __exit__
    compat.reraise(exc_type, exc_value, exc_tb)
  File "/usr/local/lib/python3.4/dist-packages/sqlalchemy/util/compat.py", line 187, in reraise
    raise value
  File "/usr/local/lib/python3.4/dist-packages/sqlalchemy/pool.py", line 1186, in _do_get
    return self._create_connection()
  File "/usr/local/lib/python3.4/dist-packages/sqlalchemy/pool.py", line 350, in _create_connection
    return _ConnectionRecord(self)
  File "/usr/local/lib/python3.4/dist-packages/sqlalchemy/pool.py", line 477, in __init__
    self.__connect(first_connect_check=True)
  File "/usr/local/lib/python3.4/dist-packages/sqlalchemy/pool.py", line 667, in __connect
    connection = pool._invoke_creator(self)
  File "/usr/local/lib/python3.4/dist-packages/sqlalchemy/engine/strategies.py", line 106, in connect
    return dialect.connect(*cargs, **cparams)
  File "/usr/local/lib/python3.4/dist-packages/sqlalchemy/engine/default.py", line 410, in connect
    return self.dbapi.connect(*cargs, **cparams)
  File "/usr/local/lib/python3.4/dist-packages/MySQLdb/__init__.py", line 86, in Connect
    return Connection(*args, **kwargs)
  File "/usr/local/lib/python3.4/dist-packages/MySQLdb/connections.py", line 204, in __init__
    super(Connection, self).__init__(*args, **kwargs2)
_mysql_exceptions.OperationalError: (1045, "Access denied for user 'hbnb_test'@'localhost' (using password: YES)")

The above exception was the direct cause of the following exception:

Traceback (most recent call last):
  File "/usr/lib/python3.4/unittest/loader.py", line 312, in _find_tests
    module = self._get_module_from_name(name)
  File "/usr/lib/python3.4/unittest/loader.py", line 290, in _get_module_from_name
    __import__(name)
  File "/home/vagrant/Holberton/AirBnB_clone_v2/tests/test_models/test_engine/test_db_storage.py", line 5, in <module>
    from models.__init__ import storage
  File "/home/vagrant/Holberton/AirBnB_clone_v2/models/__init__.py", line 16, in <module>
    storage = DBStorage()
  File "/home/vagrant/Holberton/AirBnB_clone_v2/models/engine/db_storage.py", line 37, in __init__
    Base.metadata.drop_all(bind=self.__engine)
  File "/usr/local/lib/python3.4/dist-packages/sqlalchemy/sql/schema.py", line 4031, in drop_all
    tables=tables)
  File "/usr/local/lib/python3.4/dist-packages/sqlalchemy/engine/base.py", line 1939, in _run_visitor
    with self._optional_conn_ctx_manager(connection) as conn:
  File "/usr/lib/python3.4/contextlib.py", line 59, in __enter__
    return next(self.gen)
  File "/usr/local/lib/python3.4/dist-packages/sqlalchemy/engine/base.py", line 1932, in _optional_conn_ctx_manager
    with self.contextual_connect() as conn:
  File "/usr/local/lib/python3.4/dist-packages/sqlalchemy/engine/base.py", line 2123, in contextual_connect
    self._wrap_pool_connect(self.pool.connect, None),
  File "/usr/local/lib/python3.4/dist-packages/sqlalchemy/engine/base.py", line 2162, in _wrap_pool_connect
    e, dialect, self)
  File "/usr/local/lib/python3.4/dist-packages/sqlalchemy/engine/base.py", line 1476, in _handle_dbapi_exception_noconnection
    exc_info
  File "/usr/local/lib/python3.4/dist-packages/sqlalchemy/util/compat.py", line 203, in raise_from_cause
    reraise(type(exception), exception, tb=exc_tb, cause=cause)
  File "/usr/local/lib/python3.4/dist-packages/sqlalchemy/util/compat.py", line 186, in reraise
    raise value.with_traceback(tb)
  File "/usr/local/lib/python3.4/dist-packages/sqlalchemy/engine/base.py", line 2158, in _wrap_pool_connect
    return fn()
  File "/usr/local/lib/python3.4/dist-packages/sqlalchemy/pool.py", line 403, in connect
    return _ConnectionFairy._checkout(self)
  File "/usr/local/lib/python3.4/dist-packages/sqlalchemy/pool.py", line 784, in _checkout
    fairy = _ConnectionRecord.checkout(pool)
  File "/usr/local/lib/python3.4/dist-packages/sqlalchemy/pool.py", line 532, in checkout
    rec = pool._do_get()
  File "/usr/local/lib/python3.4/dist-packages/sqlalchemy/pool.py", line 1189, in _do_get
    self._dec_overflow()
  File "/usr/local/lib/python3.4/dist-packages/sqlalchemy/util/langhelpers.py", line 66, in __exit__
    compat.reraise(exc_type, exc_value, exc_tb)
  File "/usr/local/lib/python3.4/dist-packages/sqlalchemy/util/compat.py", line 187, in reraise
    raise value
  File "/usr/local/lib/python3.4/dist-packages/sqlalchemy/pool.py", line 1186, in _do_get
    return self._create_connection()
  File "/usr/local/lib/python3.4/dist-packages/sqlalchemy/pool.py", line 350, in _create_connection
    return _ConnectionRecord(self)
  File "/usr/local/lib/python3.4/dist-packages/sqlalchemy/pool.py", line 477, in __init__
    self.__connect(first_connect_check=True)
  File "/usr/local/lib/python3.4/dist-packages/sqlalchemy/pool.py", line 667, in __connect
    connection = pool._invoke_creator(self)
  File "/usr/local/lib/python3.4/dist-packages/sqlalchemy/engine/strategies.py", line 106, in connect
    return dialect.connect(*cargs, **cparams)
  File "/usr/local/lib/python3.4/dist-packages/sqlalchemy/engine/default.py", line 410, in connect
    return self.dbapi.connect(*cargs, **cparams)
  File "/usr/local/lib/python3.4/dist-packages/MySQLdb/__init__.py", line 86, in Connect
    return Connection(*args, **kwargs)
  File "/usr/local/lib/python3.4/dist-packages/MySQLdb/connections.py", line 204, in __init__
    super(Connection, self).__init__(*args, **kwargs2)
sqlalchemy.exc.OperationalError: (_mysql_exceptions.OperationalError) (1045, "Access denied for user 'hbnb_test'@'localhost' (using password: YES)") (Background on this error at: http://sqlalche.me/e/e3q8)


======================================================================
ERROR: test_models.test_engine.test_file_storage (unittest.loader.ModuleImportFailure)
----------------------------------------------------------------------
Traceback (most recent call last):
  File "/usr/lib/python3.4/unittest/case.py", line 58, in testPartExecutor
    yield
  File "/usr/lib/python3.4/unittest/case.py", line 577, in run
    testMethod()
  File "/usr/lib/python3.4/unittest/loader.py", line 32, in testFailure
    raise exception
ImportError: Failed to import test module: test_models.test_engine.test_file_storage
Traceback (most recent call last):
  File "/usr/local/lib/python3.4/dist-packages/sqlalchemy/engine/base.py", line 2158, in _wrap_pool_connect
    return fn()
  File "/usr/local/lib/python3.4/dist-packages/sqlalchemy/pool.py", line 403, in connect
    return _ConnectionFairy._checkout(self)
  File "/usr/local/lib/python3.4/dist-packages/sqlalchemy/pool.py", line 784, in _checkout
    fairy = _ConnectionRecord.checkout(pool)
  File "/usr/local/lib/python3.4/dist-packages/sqlalchemy/pool.py", line 532, in checkout
    rec = pool._do_get()
  File "/usr/local/lib/python3.4/dist-packages/sqlalchemy/pool.py", line 1189, in _do_get
    self._dec_overflow()
  File "/usr/local/lib/python3.4/dist-packages/sqlalchemy/util/langhelpers.py", line 66, in __exit__
    compat.reraise(exc_type, exc_value, exc_tb)
  File "/usr/local/lib/python3.4/dist-packages/sqlalchemy/util/compat.py", line 187, in reraise
    raise value
  File "/usr/local/lib/python3.4/dist-packages/sqlalchemy/pool.py", line 1186, in _do_get
    return self._create_connection()
  File "/usr/local/lib/python3.4/dist-packages/sqlalchemy/pool.py", line 350, in _create_connection
    return _ConnectionRecord(self)
  File "/usr/local/lib/python3.4/dist-packages/sqlalchemy/pool.py", line 477, in __init__
    self.__connect(first_connect_check=True)
  File "/usr/local/lib/python3.4/dist-packages/sqlalchemy/pool.py", line 667, in __connect
    connection = pool._invoke_creator(self)
  File "/usr/local/lib/python3.4/dist-packages/sqlalchemy/engine/strategies.py", line 106, in connect
    return dialect.connect(*cargs, **cparams)
  File "/usr/local/lib/python3.4/dist-packages/sqlalchemy/engine/default.py", line 410, in connect
    return self.dbapi.connect(*cargs, **cparams)
  File "/usr/local/lib/python3.4/dist-packages/MySQLdb/__init__.py", line 86, in Connect
    return Connection(*args, **kwargs)
  File "/usr/local/lib/python3.4/dist-packages/MySQLdb/connections.py", line 204, in __init__
    super(Connection, self).__init__(*args, **kwargs2)
_mysql_exceptions.OperationalError: (1045, "Access denied for user 'hbnb_test'@'localhost' (using password: YES)")

The above exception was the direct cause of the following exception:

Traceback (most recent call last):
  File "/usr/lib/python3.4/unittest/loader.py", line 312, in _find_tests
    module = self._get_module_from_name(name)
  File "/usr/lib/python3.4/unittest/loader.py", line 290, in _get_module_from_name
    __import__(name)
  File "/home/vagrant/Holberton/AirBnB_clone_v2/tests/test_models/test_engine/test_file_storage.py", line 8, in <module>
    from models import storage
  File "/home/vagrant/Holberton/AirBnB_clone_v2/models/__init__.py", line 16, in <module>
    storage = DBStorage()
  File "/home/vagrant/Holberton/AirBnB_clone_v2/models/engine/db_storage.py", line 37, in __init__
    Base.metadata.drop_all(bind=self.__engine)
  File "/usr/local/lib/python3.4/dist-packages/sqlalchemy/sql/schema.py", line 4031, in drop_all
    tables=tables)
  File "/usr/local/lib/python3.4/dist-packages/sqlalchemy/engine/base.py", line 1939, in _run_visitor
    with self._optional_conn_ctx_manager(connection) as conn:
  File "/usr/lib/python3.4/contextlib.py", line 59, in __enter__
    return next(self.gen)
  File "/usr/local/lib/python3.4/dist-packages/sqlalchemy/engine/base.py", line 1932, in _optional_conn_ctx_manager
    with self.contextual_connect() as conn:
  File "/usr/local/lib/python3.4/dist-packages/sqlalchemy/engine/base.py", line 2123, in contextual_connect
    self._wrap_pool_connect(self.pool.connect, None),
  File "/usr/local/lib/python3.4/dist-packages/sqlalchemy/engine/base.py", line 2162, in _wrap_pool_connect
    e, dialect, self)
  File "/usr/local/lib/python3.4/dist-packages/sqlalchemy/engine/base.py", line 1476, in _handle_dbapi_exception_noconnection
    exc_info
  File "/usr/local/lib/python3.4/dist-packages/sqlalchemy/util/compat.py", line 203, in raise_from_cause
    reraise(type(exception), exception, tb=exc_tb, cause=cause)
  File "/usr/local/lib/python3.4/dist-packages/sqlalchemy/util/compat.py", line 186, in reraise
    raise value.with_traceback(tb)
  File "/usr/local/lib/python3.4/dist-packages/sqlalchemy/engine/base.py", line 2158, in _wrap_pool_connect
    return fn()
  File "/usr/local/lib/python3.4/dist-packages/sqlalchemy/pool.py", line 403, in connect
    return _ConnectionFairy._checkout(self)
  File "/usr/local/lib/python3.4/dist-packages/sqlalchemy/pool.py", line 784, in _checkout
    fairy = _ConnectionRecord.checkout(pool)
  File "/usr/local/lib/python3.4/dist-packages/sqlalchemy/pool.py", line 532, in checkout
    rec = pool._do_get()
  File "/usr/local/lib/python3.4/dist-packages/sqlalchemy/pool.py", line 1189, in _do_get
    self._dec_overflow()
  File "/usr/local/lib/python3.4/dist-packages/sqlalchemy/util/langhelpers.py", line 66, in __exit__
    compat.reraise(exc_type, exc_value, exc_tb)
  File "/usr/local/lib/python3.4/dist-packages/sqlalchemy/util/compat.py", line 187, in reraise
    raise value
  File "/usr/local/lib/python3.4/dist-packages/sqlalchemy/pool.py", line 1186, in _do_get
    return self._create_connection()
  File "/usr/local/lib/python3.4/dist-packages/sqlalchemy/pool.py", line 350, in _create_connection
    return _ConnectionRecord(self)
  File "/usr/local/lib/python3.4/dist-packages/sqlalchemy/pool.py", line 477, in __init__
    self.__connect(first_connect_check=True)
  File "/usr/local/lib/python3.4/dist-packages/sqlalchemy/pool.py", line 667, in __connect
    connection = pool._invoke_creator(self)
  File "/usr/local/lib/python3.4/dist-packages/sqlalchemy/engine/strategies.py", line 106, in connect
    return dialect.connect(*cargs, **cparams)
  File "/usr/local/lib/python3.4/dist-packages/sqlalchemy/engine/default.py", line 410, in connect
    return self.dbapi.connect(*cargs, **cparams)
  File "/usr/local/lib/python3.4/dist-packages/MySQLdb/__init__.py", line 86, in Connect
    return Connection(*args, **kwargs)
  File "/usr/local/lib/python3.4/dist-packages/MySQLdb/connections.py", line 204, in __init__
    super(Connection, self).__init__(*args, **kwargs2)
sqlalchemy.exc.OperationalError: (_mysql_exceptions.OperationalError) (1045, "Access denied for user 'hbnb_test'@'localhost' (using password: YES)") (Background on this error at: http://sqlalche.me/e/e3q8)


----------------------------------------------------------------------
Ran 168 tests in 0.078s

FAILED (errors=3, skipped=165)
